# 第12章 通过异常处理错误

​    

### 异常丢失

try-catch 中，如果不捕获异常而在 finally 中直接进行 return ，则就算会抛出异常也不会有任何输出。如：

```java
try {
    int i = 1 / 0;
} finally {
    return;
}
```

另一种异常丢失的情况：

```java
try {
    try {
        throw new RuntimeException();
    } finally {
        int i = 1 / 0;
    }
} finally {
    System.out.println("End.");
}
```

最后输出时会发现，只会输出 `java.lang.ArithmeticException: / by zero` ，而不会输出 RuntimeException 信息。

​    

### 「被检查的异常」问题

**问题：**

有时候可能程序员并没有准备好去处理抛出的异常，但是编译器会提醒需要强制用 catch 捕获。这样强行处理，可能会在之后发生异常丢失的问题。

**解决方法：**

用 RuntimeException 来包装「被检查的异常」。

即不使用 throws ，在 catch 中抛出异常。这样可以在准备好去捕获异常的时候去处理该异常。如：

```java
public static void f(int x) {
    try {
        if (x == 1)
            throw new FileNotFoundException();
        else throw new IOException();
    } catch(Exception e) {
        // 捕获并把上面两种异常都装进 RuntimeException 中
        throw new RuntimeException(e);
    }
}
public static void main(String[] args) {
    // 可以不用去处理异常
    f(1);
    // 如果准备好去处理该异常，可以使用 try-catch 来捕获并处理
    try {
        f(1);
    } catch(RuntimeException e) {
        try {
            throw e.getCause();
        } catch(FileNotFoundException e) {
            // 处理 FileNotFoundException
        } catch(IOException e) {
            // 处理 IOException
        }
    }
}
```

在这里也可以自己写一个 RuntimeException 的子类，在子类中进行捕获和处理。